#VRML_SIM R2023b utf8
# license: Apache License 2.0
# license url: http://www.apache.org/licenses/LICENSE-2.0
# This is a proto file for Webots for the Onshape
# Extracted from: C:\Users\TANAY SHAH\OneDrive\Desktop\PDEU\Projects\Semester 3\IIT Gandhinagar\Leadphand\Code\LEAP_Hand_Sim\assets\leap_hand\robot.urdf

PROTO Onshape [
  field  SFVec3f     translation     0 0 0
  field  SFRotation  rotation        0 0 1 0
  field  SFString    name            "Onshape"  # Is `Robot.name`.
  field  SFString    controller      "void"     # Is `Robot.controller`.
  field  MFString    controllerArgs  []         # Is `Robot.controllerArgs`.
  field  SFString    customData      ""         # Is `Robot.customData`.
  field  SFBool      supervisor      FALSE      # Is `Robot.supervisor`.
  field  SFBool      synchronization TRUE       # Is `Robot.synchronization`.
  field  SFBool      selfCollision   FALSE      # Is `Robot.selfCollision`.
]
{
  Robot {
    translation IS translation
    rotation IS rotation
    controller IS controller
    controllerArgs IS controllerArgs
    customData IS customData
    supervisor IS supervisor
    synchronization IS synchronization
    selfCollision IS selfCollision
    children [
      Pose {
        translation -0.020095 0.025758 -0.034722
        children [
          Shape {
            appearance DEF palm_lower_material PBRAppearance {
              baseColor 0.603922 0.149020 0.149020
              roughness 1.000000
              metalness 0
            }
            geometry DEF palm_lower Mesh {
              url "palm_lower.stl"
            }
          }
        ]
      }
      HingeJoint {
        jointParameters HingeJointParameters {
          axis -0.000000 1.000000 0.000000
          anchor -0.007095 0.023058 -0.018722
        }
        device [
          RotationalMotor {
            name "1"
            maxVelocity 8.48
            minPosition -0.314
            maxPosition 2.23
            maxTorque 0.95
          }
          PositionSensor {
            name "1_sensor"
          }
        ]
        endPoint Solid {
          translation -0.007095 0.023058 -0.018722
          rotation 0.577350 0.577350 -0.577350 2.094395
          children [
            Pose {
              translation 0.008407 0.007766 0.014657
              children [
                Shape {
                  appearance DEF mcp_joint_material PBRAppearance {
                    baseColor 0.866667 0.866667 0.050980
                    roughness 1.000000
                    metalness 0
                  }
                  geometry DEF mcp_joint Mesh {
                    url "mcp_joint.stl"
                  }
                }
              ]
            }
            HingeJoint {
              jointParameters HingeJointParameters {
                axis 1.000000 -0.000000 0.000000
                anchor -0.012200 0.038100 0.014500
              }
              device [
                RotationalMotor {
                  name "0"
                  maxVelocity 8.48
                  minPosition -1.047
                  maxPosition 1.047
                  maxTorque 0.95
                }
                PositionSensor {
                  name "0_sensor"
                }
              ]
              endPoint Solid {
                translation -0.012200 0.038100 0.014500
                rotation -0.577350 -0.577350 0.577350 2.094395
                children [
                  Pose {
                    translation 0.009643 0.000300 0.000784
                    rotation -0.577350 -0.577350 -0.577350 2.094395
                    children [
                      Shape {
                        appearance DEF pip_material PBRAppearance {
                          baseColor 0.749020 0.749020 0.749020
                          roughness 1.000000
                          metalness 0
                        }
                        geometry DEF pip Mesh {
                          url "pip.stl"
                        }
                      }
                    ]
                  }
                  HingeJoint {
                    jointParameters HingeJointParameters {
                      axis 0.000000 1.000000 -0.000000
                      anchor 0.015000 0.014300 -0.013000
                    }
                    device [
                      RotationalMotor {
                        name "2"
                        maxVelocity 8.48
                        minPosition -0.506
                        maxPosition 1.885
                        maxTorque 0.95
                      }
                      PositionSensor {
                        name "2_sensor"
                      }
                    ]
                    endPoint Solid {
                      translation 0.015000 0.014300 -0.013000
                      rotation 0.577350 -0.577350 0.577350 2.094395
                      children [
                        Pose {
                          translation 0.021133 -0.008432 0.009785
                          rotation -1.000000 -0.000000 0.000000 3.141593
                          children [
                            Shape {
                              appearance DEF dip_material PBRAppearance {
                                baseColor 0.866667 0.866667 0.050980
                                roughness 1.000000
                                metalness 0
                              }
                              geometry DEF dip Mesh {
                                url "dip.stl"
                              }
                            }
                          ]
                        }
                        HingeJoint {
                          jointParameters HingeJointParameters {
                            axis 0.000000 0.000000 -1.000000
                            anchor -0.000000 -0.036100 0.000200
                          }
                          device [
                            RotationalMotor {
                              name "3"
                              maxVelocity 8.48
                              minPosition -0.366
                              maxPosition 2.042
                              maxTorque 0.95
                            }
                            PositionSensor {
                              name "3_sensor"
                            }
                          ]
                          endPoint Solid {
                            translation -0.000000 -0.036100 0.000200
                            children [
                              Pose {
                                translation 0.013286 -0.006114 0.014500
                                rotation 1.000000 0.000000 -0.000000 3.141593
                                children [
                                  Shape {
                                    appearance DEF fingertip_material PBRAppearance {
                                      baseColor 0.866667 0.866667 0.050980
                                      roughness 1.000000
                                      metalness 0
                                    }
                                    geometry DEF fingertip Mesh {
                                      url "fingertip.stl"
                                    }
                                  }
                                ]
                              }
                            ]
                            name "fingertip"
                            boundingObject Pose {
                              translation 0.013286 -0.006114 0.014500
                              rotation 1.000000 0.000000 -0.000000 3.141593
                              children [
                                USE fingertip
                              ]
                            }
                            physics Physics {
                              density -1
                              mass 0.016000
                              centerOfMass [ 0.000000 0.000000 0.000000 ]
                              inertiaMatrix [
                                3.368000e-06 1.556000e-06 2.863000e-06
                                1.150000e-07 0.000000e+00 0.000000e+00
                              ]
                            }
                          }
                        }
                      ]
                      name "dip"
                      boundingObject Pose {
                        translation 0.021133 -0.008432 0.009785
                        rotation -1.000000 -0.000000 0.000000 3.141593
                        children [
                          USE dip
                        ]
                      }
                      physics Physics {
                        density -1
                        mass 0.037000
                        centerOfMass [ 0.000000 0.000000 0.000000 ]
                        inertiaMatrix [
                          5.542000e-06 5.727000e-06 6.682000e-06
                          -6.070000e-07 -1.700000e-08 -2.300000e-08
                        ]
                      }
                    }
                  }
                ]
                name "pip"
                boundingObject Pose {
                  translation 0.009643 0.000300 0.000784
                  rotation -0.577350 -0.577350 -0.577350 2.094395
                  children [
                    USE pip
                  ]
                }
                physics Physics {
                  density -1
                  mass 0.032000
                  centerOfMass [ 0.000000 0.000000 0.000000 ]
                  inertiaMatrix [
                    4.798000e-06 2.862000e-06 4.234000e-06
                    1.200000e-08 4.000000e-09 1.100000e-08
                  ]
                }
              }
            }
          ]
          name "mcp_joint"
          boundingObject Pose {
            translation 0.008407 0.007766 0.014657
            children [
              USE mcp_joint
            ]
          }
          physics Physics {
            density -1
            mass 0.044000
            centerOfMass [ 0.000000 0.000000 0.000000 ]
            inertiaMatrix [
              1.149900e-05 7.796000e-06 1.475900e-05
              3.049000e-06 1.210000e-07 1.120000e-07
            ]
          }
        }
      }
      HingeJoint {
        jointParameters HingeJointParameters {
          axis -0.000000 1.000000 -0.000000
          anchor -0.007095 -0.022392 -0.018722
        }
        device [
          RotationalMotor {
            name "5"
            maxVelocity 8.48
            minPosition -0.314
            maxPosition 2.23
            maxTorque 0.95
          }
          PositionSensor {
            name "5_sensor"
          }
        ]
        endPoint Solid {
          translation -0.007095 -0.022392 -0.018722
          rotation 0.577350 0.577350 -0.577350 2.094395
          children [
            Pose {
              translation 0.008407 0.007766 0.014657
              children [
                Shape {
                  appearance USE mcp_joint_material
                  geometry USE mcp_joint
                }
              ]
            }
            HingeJoint {
              jointParameters HingeJointParameters {
                axis 1.000000 -0.000000 0.000000
                anchor -0.012200 0.038100 0.014500
              }
              device [
                RotationalMotor {
                  name "4"
                  maxVelocity 8.48
                  minPosition -1.047
                  maxPosition 1.047
                  maxTorque 0.95
                }
                PositionSensor {
                  name "4_sensor"
                }
              ]
              endPoint Solid {
                translation -0.012200 0.038100 0.014500
                rotation -0.577350 -0.577350 0.577350 2.094395
                children [
                  Pose {
                    translation 0.009643 0.000300 0.000784
                    rotation -0.577350 -0.577350 -0.577350 2.094395
                    children [
                      Shape {
                        appearance USE pip_material
                        geometry USE pip
                      }
                    ]
                  }
                  HingeJoint {
                    jointParameters HingeJointParameters {
                      axis 0.000000 1.000000 -0.000000
                      anchor 0.015000 0.014300 -0.013000
                    }
                    device [
                      RotationalMotor {
                        name "6"
                        maxVelocity 8.48
                        minPosition -0.506
                        maxPosition 1.885
                        maxTorque 0.95
                      }
                      PositionSensor {
                        name "6_sensor"
                      }
                    ]
                    endPoint Solid {
                      translation 0.015000 0.014300 -0.013000
                      rotation 0.577350 -0.577350 0.577350 2.094395
                      children [
                        Pose {
                          translation 0.021133 -0.008432 0.009785
                          rotation -1.000000 -0.000000 0.000000 3.141593
                          children [
                            Shape {
                              appearance USE dip_material
                              geometry USE dip
                            }
                          ]
                        }
                        HingeJoint {
                          jointParameters HingeJointParameters {
                            axis 0.000000 0.000000 -1.000000
                            anchor 0.000000 -0.036100 0.000200
                          }
                          device [
                            RotationalMotor {
                              name "7"
                              maxVelocity 8.48
                              minPosition -0.366
                              maxPosition 2.042
                              maxTorque 0.95
                            }
                            PositionSensor {
                              name "7_sensor"
                            }
                          ]
                          endPoint Solid {
                            translation 0.000000 -0.036100 0.000200
                            children [
                              Pose {
                                translation 0.013286 -0.006114 0.014500
                                rotation 1.000000 0.000000 0.000000 3.141593
                                children [
                                  Shape {
                                    appearance USE fingertip_material
                                    geometry USE fingertip
                                  }
                                ]
                              }
                            ]
                            name "fingertip_2"
                            boundingObject Pose {
                              translation 0.013286 -0.006114 0.014500
                              rotation 1.000000 0.000000 0.000000 3.141593
                              children [
                                USE fingertip
                              ]
                            }
                            physics Physics {
                              density -1
                              mass 0.016000
                              centerOfMass [ 0.000000 0.000000 0.000000 ]
                              inertiaMatrix [
                                3.368000e-06 1.556000e-06 2.863000e-06
                                1.150000e-07 0.000000e+00 0.000000e+00
                              ]
                            }
                          }
                        }
                      ]
                      name "dip_2"
                      boundingObject Pose {
                        translation 0.021133 -0.008432 0.009785
                        rotation -1.000000 -0.000000 0.000000 3.141593
                        children [
                          USE dip
                        ]
                      }
                      physics Physics {
                        density -1
                        mass 0.037000
                        centerOfMass [ 0.000000 0.000000 0.000000 ]
                        inertiaMatrix [
                          5.542000e-06 5.727000e-06 6.682000e-06
                          -6.070000e-07 -1.700000e-08 -2.300000e-08
                        ]
                      }
                    }
                  }
                ]
                name "pip_2"
                boundingObject Pose {
                  translation 0.009643 0.000300 0.000784
                  rotation -0.577350 -0.577350 -0.577350 2.094395
                  children [
                    USE pip
                  ]
                }
                physics Physics {
                  density -1
                  mass 0.032000
                  centerOfMass [ 0.000000 0.000000 0.000000 ]
                  inertiaMatrix [
                    4.798000e-06 2.862000e-06 4.234000e-06
                    1.200000e-08 4.000000e-09 1.100000e-08
                  ]
                }
              }
            }
          ]
          name "mcp_joint_2"
          boundingObject Pose {
            translation 0.008407 0.007766 0.014657
            children [
              USE mcp_joint
            ]
          }
          physics Physics {
            density -1
            mass 0.044000
            centerOfMass [ 0.000000 0.000000 0.000000 ]
            inertiaMatrix [
              1.149900e-05 7.796000e-06 1.475900e-05
              3.049000e-06 1.210000e-07 1.120000e-07
            ]
          }
        }
      }
      HingeJoint {
        jointParameters HingeJointParameters {
          axis -0.000000 1.000000 0.000000
          anchor -0.007095 -0.067842 -0.018722
        }
        device [
          RotationalMotor {
            name "9"
            maxVelocity 8.48
            minPosition -0.314
            maxPosition 2.23
            maxTorque 0.95
          }
          PositionSensor {
            name "9_sensor"
          }
        ]
        endPoint Solid {
          translation -0.007095 -0.067842 -0.018722
          rotation 0.577350 0.577350 -0.577350 2.094395
          children [
            Pose {
              translation 0.008407 0.007766 0.014657
              children [
                Shape {
                  appearance USE mcp_joint_material
                  geometry USE mcp_joint
                }
              ]
            }
            HingeJoint {
              jointParameters HingeJointParameters {
                axis 1.000000 -0.000000 0.000000
                anchor -0.012200 0.038100 0.014500
              }
              device [
                RotationalMotor {
                  name "8"
                  maxVelocity 8.48
                  minPosition -1.047
                  maxPosition 1.047
                  maxTorque 0.95
                }
                PositionSensor {
                  name "8_sensor"
                }
              ]
              endPoint Solid {
                translation -0.012200 0.038100 0.014500
                rotation -0.577350 -0.577350 0.577350 2.094395
                children [
                  Pose {
                    translation 0.009643 0.000300 0.000784
                    rotation -0.577350 -0.577350 -0.577350 2.094395
                    children [
                      Shape {
                        appearance USE pip_material
                        geometry USE pip
                      }
                    ]
                  }
                  HingeJoint {
                    jointParameters HingeJointParameters {
                      axis 0.000000 1.000000 -0.000000
                      anchor 0.015000 0.014300 -0.013000
                    }
                    device [
                      RotationalMotor {
                        name "10"
                        maxVelocity 8.48
                        minPosition -0.506
                        maxPosition 1.885
                        maxTorque 0.95
                      }
                      PositionSensor {
                        name "10_sensor"
                      }
                    ]
                    endPoint Solid {
                      translation 0.015000 0.014300 -0.013000
                      rotation 0.577350 -0.577350 0.577350 2.094395
                      children [
                        Pose {
                          translation 0.021133 -0.008432 0.009785
                          rotation -1.000000 -0.000000 -0.000000 3.141593
                          children [
                            Shape {
                              appearance USE dip_material
                              geometry USE dip
                            }
                          ]
                        }
                        HingeJoint {
                          jointParameters HingeJointParameters {
                            axis 0.000000 0.000000 -1.000000
                            anchor 0.000000 -0.036100 0.000200
                          }
                          device [
                            RotationalMotor {
                              name "11"
                              maxVelocity 8.48
                              minPosition -0.366
                              maxPosition 2.042
                              maxTorque 0.95
                            }
                            PositionSensor {
                              name "11_sensor"
                            }
                          ]
                          endPoint Solid {
                            translation 0.000000 -0.036100 0.000200
                            children [
                              Pose {
                                translation 0.013286 -0.006114 0.014500
                                rotation 1.000000 0.000000 -0.000000 3.141593
                                children [
                                  Shape {
                                    appearance USE fingertip_material
                                    geometry USE fingertip
                                  }
                                ]
                              }
                            ]
                            name "fingertip_3"
                            boundingObject Pose {
                              translation 0.013286 -0.006114 0.014500
                              rotation 1.000000 0.000000 -0.000000 3.141593
                              children [
                                USE fingertip
                              ]
                            }
                            physics Physics {
                              density -1
                              mass 0.016000
                              centerOfMass [ 0.000000 0.000000 0.000000 ]
                              inertiaMatrix [
                                3.368000e-06 1.556000e-06 2.863000e-06
                                1.150000e-07 0.000000e+00 0.000000e+00
                              ]
                            }
                          }
                        }
                      ]
                      name "dip_3"
                      boundingObject Pose {
                        translation 0.021133 -0.008432 0.009785
                        rotation -1.000000 -0.000000 -0.000000 3.141593
                        children [
                          USE dip
                        ]
                      }
                      physics Physics {
                        density -1
                        mass 0.037000
                        centerOfMass [ 0.000000 0.000000 0.000000 ]
                        inertiaMatrix [
                          5.542000e-06 5.727000e-06 6.682000e-06
                          -6.070000e-07 -1.700000e-08 -2.300000e-08
                        ]
                      }
                    }
                  }
                ]
                name "pip_3"
                boundingObject Pose {
                  translation 0.009643 0.000300 0.000784
                  rotation -0.577350 -0.577350 -0.577350 2.094395
                  children [
                    USE pip
                  ]
                }
                physics Physics {
                  density -1
                  mass 0.032000
                  centerOfMass [ 0.000000 0.000000 0.000000 ]
                  inertiaMatrix [
                    4.798000e-06 2.862000e-06 4.234000e-06
                    1.200000e-08 4.000000e-09 1.100000e-08
                  ]
                }
              }
            }
          ]
          name "mcp_joint_3"
          boundingObject Pose {
            translation 0.008407 0.007766 0.014657
            children [
              USE mcp_joint
            ]
          }
          physics Physics {
            density -1
            mass 0.044000
            centerOfMass [ 0.000000 0.000000 0.000000 ]
            inertiaMatrix [
              1.149900e-05 7.796000e-06 1.475900e-05
              3.049000e-06 1.210000e-07 1.120000e-07
            ]
          }
        }
      }
      HingeJoint {
        jointParameters HingeJointParameters {
          axis -1.000000 -0.000000 -0.000000
          anchor -0.069395 -0.001242 -0.021622
        }
        device [
          RotationalMotor {
            name "12"
            maxVelocity 8.48
            minPosition -0.349
            maxPosition 2.094
            maxTorque 0.95
          }
          PositionSensor {
            name "12_sensor"
          }
        ]
        endPoint Solid {
          translation -0.069395 -0.001242 -0.021622
          rotation -0.000000 1.000000 0.000000 1.570796
          children [
            Pose {
              translation -0.005357 0.000300 0.000784
              rotation -0.577350 -0.577350 -0.577350 2.094395
              children [
                Shape {
                  appearance USE pip_material
                  geometry USE pip
                }
              ]
            }
            HingeJoint {
              jointParameters HingeJointParameters {
                axis 0.000000 1.000000 -0.000000
                anchor -0.000000 0.014300 -0.013000
              }
              device [
                RotationalMotor {
                  name "13"
                  maxVelocity 8.48
                  minPosition -0.47
                  maxPosition 2.443
                  maxTorque 0.95
                }
                PositionSensor {
                  name "13_sensor"
                }
              ]
              endPoint Solid {
                translation -0.000000 0.014300 -0.013000
                rotation 0.577350 -0.577350 0.577350 2.094395
                children [
                  Pose {
                    translation 0.011962 -0.000000 -0.015853
                    rotation 1.000000 0.000000 -0.000000 1.570796
                    children [
                      Shape {
                        appearance DEF thumb_pip_material PBRAppearance {
                          baseColor 0.866667 0.866667 0.050980
                          roughness 1.000000
                          metalness 0
                        }
                        geometry DEF thumb_pip Mesh {
                          url "thumb_pip.stl"
                        }
                      }
                    ]
                  }
                  HingeJoint {
                    jointParameters HingeJointParameters {
                      axis -0.000000 -1.000000 -0.000000
                      anchor 0.000000 0.014500 -0.017000
                    }
                    device [
                      RotationalMotor {
                        name "14"
                        maxVelocity 8.48
                        minPosition -1.2
                        maxPosition 1.9
                        maxTorque 0.95
                      }
                      PositionSensor {
                        name "14_sensor"
                      }
                    ]
                    endPoint Solid {
                      translation 0.000000 0.014500 -0.017000
                      rotation -1.000000 0.000000 -0.000000 1.570796
                      children [
                        Pose {
                          translation 0.043969 0.057953 -0.008629
                          children [
                            Shape {
                              appearance DEF thumb_dip_material PBRAppearance {
                                baseColor 0.866667 0.866667 0.050980
                                roughness 1.000000
                                metalness 0
                              }
                              geometry DEF thumb_dip Mesh {
                                url "thumb_dip.stl"
                              }
                            }
                          ]
                        }
                        HingeJoint {
                          jointParameters HingeJointParameters {
                            axis 0.000000 -0.000000 -1.000000
                            anchor -0.000000 0.046600 0.000200
                          }
                          device [
                            RotationalMotor {
                              name "15"
                              maxVelocity 8.48
                              minPosition -1.34
                              maxPosition 1.88
                              maxTorque 0.95
                            }
                            PositionSensor {
                              name "15_sensor"
                            }
                          ]
                          endPoint Solid {
                            translation -0.000000 0.046600 0.000200
                            rotation -0.000000 0.000000 1.000000 3.141593
                            children [
                              Pose {
                                translation 0.062560 0.078460 0.048993
                                children [
                                  Shape {
                                    appearance DEF thumb_fingertip_material PBRAppearance {
                                      baseColor 0.603922 0.149020 0.149020
                                      roughness 1.000000
                                      metalness 0
                                    }
                                    geometry DEF thumb_fingertip Mesh {
                                      url "thumb_fingertip.stl"
                                    }
                                  }
                                ]
                              }
                            ]
                            name "thumb_fingertip"
                            boundingObject Pose {
                              translation 0.062560 0.078460 0.048993
                              children [
                                USE thumb_fingertip
                              ]
                            }
                            physics Physics {
                              density -1
                              mass 0.049000
                              centerOfMass [ 0.000000 0.000000 0.000000 ]
                              inertiaMatrix [
                                2.037200e-05 4.336000e-06 1.984500e-05
                                -4.890000e-07 -3.000000e-08 -9.700000e-08
                              ]
                            }
                          }
                        }
                      ]
                      name "thumb_dip"
                      boundingObject Pose {
                        translation 0.043969 0.057953 -0.008629
                        children [
                          USE thumb_dip
                        ]
                      }
                      physics Physics {
                        density -1
                        mass 0.038000
                        centerOfMass [ 0.000000 0.000000 0.000000 ]
                        inertiaMatrix [
                          8.474000e-06 3.841000e-06 7.679000e-06
                          2.410000e-07 2.600000e-08 2.500000e-08
                        ]
                      }
                    }
                  }
                ]
                name "thumb_pip"
                boundingObject Pose {
                  translation 0.011962 -0.000000 -0.015853
                  rotation 1.000000 0.000000 -0.000000 1.570796
                  children [
                    USE thumb_pip
                  ]
                }
                physics Physics {
                  density -1
                  mass 0.003000
                  centerOfMass [ 0.000000 0.000000 0.000000 ]
                  inertiaMatrix [
                    5.930000e-07 5.490000e-07 2.240000e-07
                    0.000000e+00 0.000000e+00 0.000000e+00
                  ]
                }
              }
            }
          ]
          name "pip_4"
          boundingObject Pose {
            translation -0.005357 0.000300 0.000784
            rotation -0.577350 -0.577350 -0.577350 2.094395
            children [
              USE pip
            ]
          }
          physics Physics {
            density -1
            mass 0.032000
            centerOfMass [ 0.000000 0.000000 0.000000 ]
            inertiaMatrix [
              4.798000e-06 2.862000e-06 4.234000e-06
              1.200000e-08 4.000000e-09 1.100000e-08
            ]
          }
        }
      }
    ]
    name IS name
    boundingObject Pose {
      translation -0.020095 0.025758 -0.034722
      children [
        USE palm_lower
      ]
    }
    physics Physics {
      density -1
      mass 0.237000
      centerOfMass [ 0.000000 0.000000 0.000000 ]
      inertiaMatrix [
        3.540940e-04 2.609150e-04 5.292570e-04
        -1.193000e-06 -2.445000e-06 -2.905000e-06
      ]
    }
  }
}
